Traceback (most recent call last):
  File "C:\Users\renso\anaconda3\envs\automated-string-cleaning\lib\site-packages\pandas\core\indexes\base.py", line 3361, in get_loc
    return self._engine.get_loc(casted_key)
  File "pandas\_libs\index.pyx", line 76, in pandas._libs.index.IndexEngine.get_loc
  File "pandas\_libs\index.pyx", line 108, in pandas._libs.index.IndexEngine.get_loc
  File "pandas\_libs\hashtable_class_helper.pxi", line 5198, in pandas._libs.hashtable.PyObjectHashTable.get_item
  File "pandas\_libs\hashtable_class_helper.pxi", line 5206, in pandas._libs.hashtable.PyObjectHashTable.get_item
KeyError: 'None'

The above exception was the direct cause of the following exception:

Traceback (most recent call last):
  File "C:\Rens\Universiteit\Master\Jaar 2\Q1\Capita Selecta\automated-string-cleaning\auto_string_cleaner\testing_datasets.py", line 95, in <module>
    X, y = main.run(data=X, y=y)
  File "C:\Rens\Universiteit\Master\Jaar 2\Q1\Capita Selecta\automated-string-cleaning\auto_string_cleaner\main.py", line 178, in run
    data, datatypes = handle_outlier_vals(data, datatypes, outlier_vals, names)
  File "C:\Rens\Universiteit\Master\Jaar 2\Q1\Capita Selecta\automated-string-cleaning\auto_string_cleaner\main.py", line 73, in handle_outlier_vals
    return handle_outliers.run(df, datatypes, outlier_vals, names)
  File "C:\Rens\Universiteit\Master\Jaar 2\Q1\Capita Selecta\automated-string-cleaning\auto_string_cleaner\modules\handle_outliers.py", line 109, in run
    if ((unique_freq.at[out] / len(df) < 0.025 and len(unique_vals) / len(df) < 0.8)
  File "C:\Users\renso\anaconda3\envs\automated-string-cleaning\lib\site-packages\pandas\core\indexing.py", line 2275, in __getitem__
    return super().__getitem__(key)
  File "C:\Users\renso\anaconda3\envs\automated-string-cleaning\lib\site-packages\pandas\core\indexing.py", line 2222, in __getitem__
    return self.obj._get_value(*key, takeable=self._takeable)
  File "C:\Users\renso\anaconda3\envs\automated-string-cleaning\lib\site-packages\pandas\core\series.py", line 1051, in _get_value
    loc = self.index.get_loc(label)
  File "C:\Users\renso\anaconda3\envs\automated-string-cleaning\lib\site-packages\pandas\core\indexes\base.py", line 3363, in get_loc
    raise KeyError(key) from err
KeyError: 'None'
